File: test.UXD
; C:\DIFFDAT1\Jingfan\BL_125_001_O2\Reflectivity\Refl_all_in_one.raw(Diffrac Plus V1.01 file) converted by XCH V1.0
_FILEVERSION=2
_SITE='James-franck-Stra e 1, 85748 Garching'
_USER='Physik Department E21'
_SAMPLE_CHANGER_CODE=0
_ATTACHMENTS_CODE=0
_GONIOMETER_RADIUS=217.500000
_FIXED_DIVSLIT=0.600000
_FIXED_SAMPLESLIT=1.000000
_SOLLER_SLITS='Y'
_FIXED_DETSLIT=0.100000
_MONOCHROMATOR=0
; None
_THIN_FILM='N'
_BETA_FILTER='Y'
_FIXED_ANTISLIT=0.200000
_ANALYZER_CODE=0
; None
_DATEMEASURED='21-Jun-2015 02:57:58'
_WL_UNIT='A'
_WL1=1.540600
_WL2=1.544390
_WL3=1.392220
_WLRATIO=0.500000
_ANODE='Cu'
; (Data for Range number 1)
_DRIVE='COUPLED'
_STEPTIME=25.600000
_STEPSIZE=0.010000
_STEPMODE='S'
_START=0.200000
_THETA=0.100000
_2THETA=0.200000
_KHI=0.000000
_PHI=0.000000
_X=0.000000
_Y=0.000000
_Z=0.000000
_DIVERGENCE=0.000000
_ANTISCATTER=0.000000
_DETECTOR=1
; S.C.
_HV=799.799988
_GAIN=2.000000
_LLD=0.900000
_ULD=2.000000
_DETECTORSLIT='in'
_AUX1=0.000000
_AUX2=0.000000
_AUX3=0.000000
_DELAY=1.000000
_TIMESTARTED=5.000000
_TEMP_RATE=-1.000000
_TEMP_DELAY=-1.000000
_KV=40
_MA=40
_RANGE_WL=1.540600
_3DPLANE=0
_2THETACPS
   0.2000    1646.2
   0.2100    1775.9
   0.2200    1872.2
   0.2300    1981.5
   0.2400    2095.5
   0.2500    2182.1
   0.2600    2283.2
   0.2700    2390.4
   0.2800    2492.3
   0.2900    2589.6
   0.3000    2694.8
   0.3100    2767.3
   0.3200    2893.6
   0.3300    2944.2
   0.3400    3043.9
   0.3500    3118.9
   0.3600    3194.0
   0.3700    3292.6
   0.3800    3371.8
   0.3900    3431.4
   0.4000    3506.8
   0.4100    3574.6
   0.4200    3631.4
   0.4300    3680.1
   0.4400    3762.7
   0.4500    3801.0
   0.4600    3870.4
   0.4700    3872.9
   0.4800    3934.0
   0.4900    3941.6
   0.5000    3984.6
   0.5100    3996.6
   0.5200    4043.4
   0.5300    4011.4
   0.5400    4056.9
   0.5500    3996.8
   0.5600    4042.5
   0.5700    4000.5
   0.5800    3980.1
   0.5900    3880.1
   0.6000    3822.2
   0.6100    3678.6
   0.6200    3573.8
   0.6300    3351.1
   0.6400    3230.1
   0.6500    3010.9
   0.6600    2846.3
   0.6700    2600.4
   0.6800    2423.7
   0.6900    2225.3
   0.7000    2024.6
   0.7100    1806.8
   0.7200    1638.1
   0.7300    1446.6
   0.7400    1281.9
   0.7500    1116.5
   0.7600    970.74
   0.7700    844.57
   0.7800    733.87
   0.7900    629.37
   0.8000    550.98
   0.8100    484.37
   0.8200    426.33
   0.8300    377.11
   0.8400    345.74
   0.8500    318.95
   0.8600    295.12
   0.8700    275.27
   0.8800    258.83
   0.8900    250.12
   0.9000    246.33
   0.9100    232.30
   0.9200    229.84
   0.9300    218.32
   0.9400    206.25
   0.9500    196.99
   0.9600    196.87
   0.9700    185.86
   0.9800    181.56
   0.9900    167.58
   1.0000    160.08
   1.0100    148.67
   1.0200    138.16
   1.0300    125.90
   1.0400    120.16
   1.0500    110.35
   1.0600    106.72
   1.0700    93.477
   1.0800    89.687
   1.0900    75.625
   1.1000    77.070
   1.1100    68.594
   1.1200    67.305
   1.1300    60.508
   1.1400    60.859
   1.1500    55.625
   1.1600    54.570
   1.1700    52.148
   1.1800    53.633
   1.1900    54.844
   1.2000    54.102
   1.2100    53.516
   1.2200    56.211
   1.2300    56.328
   1.2400    55.625
   1.2500    56.523
; (Data for Range number 2)
_DRIVE='COUPLED'
_STEPTIME=51.200001
_STEPSIZE=0.010000
_STEPMODE='S'
_START=1.150000
_THETA=0.575000
_2THETA=1.150000
_KHI=0.000000
_PHI=0.000000
_X=0.000000
_Y=0.000000
_Z=0.000000
_DIVERGENCE=0.000000
_ANTISCATTER=0.000000
_DETECTOR=1
; S.C.
_HV=799.799988
_GAIN=2.000000
_LLD=0.900000
_ULD=2.000000
_DETECTORSLIT='out'
_AUX1=0.000000
_AUX2=0.000000
_AUX3=0.000000
_DELAY=1.000000
_TIMESTARTED=2724.000000
_TEMP_RATE=-1.000000
_TEMP_DELAY=-1.000000
_KV=40
_MA=40
_RANGE_WL=1.540600
_3DPLANE=0
_2THETACPS
   1.1500   48279.7
   1.1600   48349.0
   1.1700   47718.7
   1.1800   47586.5
   1.1900   47214.1
   1.2000   47843.6
   1.2100   48347.9
   1.2200   49026.8
   1.2300   49467.4
   1.2400   50417.6
   1.2500   50872.1
   1.2600   51399.0
   1.2700   51368.6
   1.2800   52104.7
   1.2900   52210.4
   1.3000   52129.5
   1.3100   51436.5
   1.3200   51302.9
   1.3300   50389.5
   1.3400   49635.2
   1.3500   47922.5
   1.3600   46832.4
   1.3700   45226.0
   1.3800   43650.8
   1.3900   41420.1
   1.4000   39730.5
   1.4100   37576.8
   1.4200   35681.1
   1.4300   33220.3
   1.4400   31250.2
   1.4500   29099.8
   1.4600   27208.4
   1.4700   25098.4
   1.4800   23439.8
   1.4900   21729.9
   1.5000   20314.3
   1.5100   18797.9
   1.5200   17634.2
   1.5300   16495.8
   1.5400   15661.7
   1.5500   14691.8
   1.5600   14126.7
   1.5700   13467.3
   1.5800   13065.0
   1.5900   12619.1
   1.6000   12443.8
   1.6100   12181.1
   1.6200   12162.8
   1.6300   11984.4
   1.6400   12020.0
   1.6500   11919.6
   1.6600   11999.3
   1.6700   11912.9
   1.6800   12008.3
   1.6900   11869.6
   1.7000   11921.1
   1.7100   11723.7
   1.7200   11715.4
   1.7300   11420.9
   1.7400   11263.1
   1.7500   10974.3
   1.7600   10758.9
   1.7700   10346.6
   1.7800   10012.4
   1.7900    9555.7
   1.8000    9216.4
   1.8100    8713.2
   1.8200    8323.8
   1.8300    7830.0
   1.8400    7454.6
   1.8500    6967.9
   1.8600    6583.1
   1.8700    6150.7
   1.8800    5803.7
   1.8900    5381.0
   1.9000    5103.2
   1.9100    4788.0
   1.9200    4565.9
   1.9300    4305.5
   1.9400    4105.2
   1.9500    3954.5
   1.9600    3852.1
   1.9700    3729.4
   1.9800    3665.4
   1.9900    3600.0
   2.0000    3584.3
   2.0100    3555.5
   2.0200    3566.7
   2.0300    3582.5
   2.0400    3646.5
   2.0500    3661.7
   2.0600    3698.0
   2.0700    3708.1
   2.0800    3793.7
   2.0900    3796.3
   2.1000    3820.9
   2.1100    3829.1
   2.1200    3864.2
   2.1300    3847.1
   2.1400    3839.6
   2.1500    3769.8
   2.1600    3768.6
   2.1700    3684.0
   2.1800    3628.4
   2.1900    3503.7
   2.2000    3434.7
   2.2100    3318.2
   2.2200    3202.2
   2.2300    3066.5
   2.2400    2961.8
   2.2500    2782.7
   2.2600    2673.6
   2.2700    2510.6
   2.2800    2376.6
   2.2900    2208.4
   2.3000    2103.0
   2.3100    1937.3
   2.3200    1830.6
   2.3300    1686.6
   2.3400    1590.1
   2.3500    1454.0
   2.3600    1384.7
   2.3700    1285.1
   2.3800    1227.3
   2.3900    1146.9
   2.4000    1105.6
   2.4100    1046.1
   2.4200    1020.4
   2.4300    991.04
   2.4400    1007.9
   2.4500    984.37
   2.4600    1002.0
   2.4700    1006.8
   2.4800    1038.5
   2.4900    1056.5
   2.5000    1084.8
   2.5100    1107.8
   2.5200    1162.5
   2.5300    1180.2
   2.5400    1223.8
   2.5500    1224.9
   2.5600    1277.7
   2.5700    1295.5
   2.5800    1322.8
   2.5900    1331.7
   2.6000    1352.5
   2.6100    1348.7
   2.6200    1357.3
   2.6300    1341.8
   2.6400    1350.0
   2.6500    1319.7
   2.6600    1298.6
   2.6700    1267.1
   2.6800    1251.6
   2.6900    1208.0
   2.7000    1167.7
   2.7100    1119.5
   2.7200    1106.3
   2.7300    1055.0
   2.7400    1004.5
   2.7500    965.27
   2.7600    927.27
   2.7700    886.62
   2.7800    858.79
   2.7900    815.04
   2.8000    797.52
   2.8100    763.71
   2.8200    741.80
   2.8300    722.89
   2.8400    711.48
   2.8500    699.80
   2.8600    694.24
   2.8700    683.59
   2.8800    694.88
   2.8900    695.23
   2.9000    702.48
   2.9100    707.29
   2.9200    723.67
   2.9300    733.65
   2.9400    748.28
   2.9500    754.18
   2.9600    776.93
   2.9700    785.64
   2.9800    785.33
   2.9900    783.16
   3.0000    810.20
   3.0100    814.59
   3.0200    821.52
   3.0300    809.02
   3.0400    818.81
   3.0500    806.54
   3.0600    793.95
   3.0700    773.09
   3.0800    766.17
   3.0900    745.31
   3.1000    734.98
   3.1100    702.07
   3.1200    678.22
   3.1300    655.23
   3.1400    632.17
   3.1500    596.52
   3.1600    568.55
   3.1700    540.21
   3.1800    518.59
   3.1900    491.48
   3.2000    469.71
   3.2100    441.46
   3.2200    412.29
   3.2300    398.77
   3.2400    375.10
   3.2500    359.57
   3.2600    346.68
   3.2700    326.76
   3.2800    320.84
   3.2900    312.83
   3.3000    311.02
   3.3100    297.15
   3.3200    306.64
   3.3300    303.89
   3.3400    309.80
   3.3500    310.96
   3.3600    318.93
   3.3700    328.07
   3.3800    330.43
   3.3900    339.53
   3.4000    348.87
   3.4100    352.01
   3.4200    359.53
   3.4300    370.18
   3.4400    380.57
   3.4500    390.49
   3.4600    395.04
   3.4700    396.02
   3.4800    399.34
   3.4900    396.50
   3.5000    393.22
   3.5100    400.14
   3.5200    393.14
   3.5300    387.01
   3.5400    384.92
   3.5500    378.85
   3.5600    371.00
   3.5700    366.60
   3.5800    351.91
   3.5900    340.29
   3.6000    329.77
   3.6100    316.70
   3.6200    308.63
   3.6300    301.04
   3.6400    284.36
   3.6500    271.68
   3.6600    259.16
   3.6700    248.87
   3.6800    244.18
   3.6900    235.84
   3.7000    227.34
   3.7100    218.87
   3.7200    215.82
   3.7300    208.36
   3.7400    209.12
   3.7500    201.25
   3.7600    205.16
   3.7700    196.82
   3.7800    205.72
   3.7900    199.14
   3.8000    204.73
   3.8100    199.71
   3.8200    204.00
   3.8300    200.39
   3.8400    203.87
   3.8500    204.18
   3.8600    208.55
   3.8700    206.13
   3.8800    205.57
   3.8900    205.62
   3.9000    206.89
   3.9100    203.42
   3.9200    204.53
   3.9300    200.78
   3.9400    196.50
   3.9500    192.58
   3.9600    189.41
   3.9700    180.53
   3.9800    178.11
   3.9900    172.73
   4.0000    165.92
   4.0100    158.16
   4.0200    151.74
   4.0300    146.54
   4.0400    135.37
   4.0500    129.65
   4.0600    124.43
   4.0700    115.72
   4.0800    107.13
   4.0900    102.93
   4.1000    100.20
   4.1100    94.414
   4.1200    90.703
   4.1300    85.996
   4.1400    83.047
   4.1500    79.414
   4.1600    79.004
   4.1700    74.473
   4.1800    77.637
   4.1900    74.258
   4.2000    72.383
   4.2100    72.227
   4.2200    73.770
   4.2300    72.773
   4.2400    74.941
   4.2500    73.281
   4.2600    75.332
   4.2700    74.707
   4.2800    77.559
   4.2900    76.934
   4.3000    78.184
   4.3100    78.398
   4.3200    77.402
   4.3300    79.043
   4.3400    79.023
   4.3500    75.742
   4.3600    77.090
   4.3700    75.449
   4.3800    74.375
   4.3900    71.719
   4.4000    72.559
   4.4100    67.734
   4.4200    67.520
   4.4300    64.727
   4.4400    63.711
   4.4500    61.387
   4.4600    59.180
   4.4700    55.371
   4.4800    53.945
   4.4900    51.426
   4.5000    47.695
   4.5100    46.758
   4.5200    45.312
   4.5300    42.480
   4.5400    40.312
   4.5500    37.773
   4.5600    36.582
   4.5700    34.238
   4.5800    32.090
   4.5900    31.426
   4.6000    30.117
   4.6100    29.648
   4.6200    27.871
   4.6300    27.539
   4.6400    26.914
   4.6500    26.719
   4.6600    26.621
   4.6700    25.664
   4.6800    25.664
   4.6900    25.586
   4.7000    26.562
   4.7100    26.660
   4.7200    26.113
   4.7300    27.031
   4.7400    27.500
   4.7500    27.461
   4.7600    25.078
   4.7700    27.285
   4.7800    28.477
   4.7900    25.703
   4.8000    27.305
   4.8100    27.070
   4.8200    26.230
   4.8300    25.547
   4.8400    26.836
   4.8500    25.000
   4.8600    25.586
   4.8700    25.430
   4.8800    25.137
   4.8900    24.375
   4.9000    22.773
   4.9100    21.738
   4.9200    22.344
   4.9300    22.695
   4.9400    21.191
   4.9500    20.859
   4.9600    19.687
   4.9700    17.910
   4.9800    18.105
   4.9900    16.699
   5.0000    17.949
   5.0100    16.484
   5.0200    16.172
   5.0300    16.484
   5.0400    15.723
   5.0500    15.332
   5.0600    15.371
   5.0700    14.590
   5.0800    15.098
   5.0900    15.332
   5.1000    15.371
   5.1100    14.219
   5.1200    15.664
   5.1300    14.648
   5.1400    15.801
   5.1500    15.957
   5.1600    15.859
   5.1700    15.566
   5.1800    17.812
   5.1900    15.937
   5.2000    16.777
   5.2100    16.699
   5.2200    17.031
   5.2300    17.285
   5.2400    17.344
   5.2500    17.109
   5.2600    17.246
   5.2700    16.172
   5.2800    17.187
   5.2900    18.047
   5.3000    16.582
   5.3100    16.035
   5.3200    15.098
   5.3300    14.648
   5.3400    15.332
   5.3500    15.605
   5.3600    14.297
   5.3700    13.613
   5.3800    13.203
   5.3900    12.402
   5.4000    12.441
   5.4100    12.266
   5.4200    11.250
   5.4300    11.270
   5.4400    10.820
   5.4500    10.371
   5.4600    9.8828
   5.4700    10.098
   5.4800    9.8828
   5.4900    8.4180
   5.5000    9.1797
   5.5100    8.2422
   5.5200    8.0664
   5.5300    8.9453
   5.5400    9.1992
   5.5500    7.9297
   5.5600    7.9687
   5.5700    7.7930
   5.5800    8.1445
   5.5900    7.9492
   5.6000    7.7344
   5.6100    7.5195
   5.6200    7.9687
   5.6300    7.6172
   5.6400    7.5000
   5.6500    8.6914
   5.6600    8.4375
   5.6700    7.0703
   5.6800    7.1484
   5.6900    7.5000
   5.7000    8.0859
   5.7100    7.6367
   5.7200    7.9102
   5.7300    7.5000
   5.7400    7.7344
   5.7500    7.2070
   5.7600    6.6992
   5.7700    6.8164
   5.7800    6.0742
   5.7900    5.9570
   5.8000    6.0547
   5.8100    6.4062
   5.8200    5.4297
   5.8300    5.7812
   5.8400    4.8828
   5.8500    5.9766
   5.8600    5.5859
   5.8700    4.9023
   5.8800    5.0000
   5.8900    5.2539
   5.9000    4.5117
   5.9100    3.9453
   5.9200    4.6094
   5.9300    3.7891
   5.9400    3.8086
   5.9500    3.6719
   5.9600    4.3945
   5.9700    3.9258
   5.9800    3.8477
   5.9900    4.0234
   6.0000    3.5742
   6.0100    3.7305
   6.0200    4.3750
   6.0300    3.6914
   6.0400    3.8086
   6.0500    3.7695
   6.0600    3.5352
   6.0700    3.9648
   6.0800    3.5352
   6.0900    3.5937
   6.1000    3.8867
   6.1100    3.6133
   6.1200    3.3984
   6.1300    3.4180
   6.1400    3.3594
   6.1500    3.3984
   6.1600    3.5352
   6.1700    3.0469
   6.1800    3.5547
   6.1900    3.2031
   6.2000    2.7148
   6.2100    2.7734
   6.2200    2.9297
   6.2300    3.1250
   6.2400    2.6172
   6.2500    2.6562
   6.2600    2.5000
   6.2700    2.2852
   6.2800    2.5977
   6.2900    2.2461
   6.3000    2.1484
   6.3100    2.3437
   6.3200    2.4805
   6.3300    2.1680
   6.3400    2.3242
   6.3500    1.9922
   6.3600    2.0117
   6.3700    2.0508
   6.3800    2.0898
   6.3900    2.0898
   6.4000    1.7969
   6.4100    1.7773
   6.4200    1.8750
   6.4300    1.7187
   6.4400    2.2070
   6.4500    1.7383
   6.4600    1.5820
   6.4700    1.6992
   6.4800    1.8945
   6.4900    1.6211
   6.5000    1.8164
   6.5100    1.9336
   6.5200    1.7773
   6.5300    1.5430
   6.5400    1.8359
   6.5500    2.1875
   6.5600    1.8750
   6.5700    2.0508
   6.5800    1.7773
   6.5900    1.8750
   6.6000    2.0312
   6.6100    1.7773
   6.6200    2.1094
   6.6300    1.8359
   6.6400    1.7578
   6.6500    2.0312
   6.6600    1.8555
   6.6700    2.0703
   6.6800    1.8359
   6.6900    1.9922
   6.7000    2.0312
   6.7100    1.7187
   6.7200    1.5820
   6.7300    1.8164
   6.7400    1.9336
   6.7500    1.5820
   6.7600    1.6602
   6.7700    1.5820
   6.7800    1.5820
   6.7900    1.9531
   6.8000    1.7773
   6.8100    1.8555
   6.8200    1.6211
   6.8300    1.3086
   6.8400    1.6406
   6.8500    1.5625
   6.8600    1.2500
   6.8700    1.6992
   6.8800    1.7578
   6.8900    1.5820
   6.9000    1.7187
   6.9100    1.6016
   6.9200    1.7969
   6.9300    1.7773
   6.9400    1.4453
   6.9500    1.4258
   6.9600    1.6992
   6.9700    1.6992
   6.9800    1.8164
   6.9900    1.5820
   7.0000    1.7773
   7.0100    1.4453
   7.0200    1.8555
   7.0300    1.6406
   7.0400    1.6992
   7.0500    2.0508
   7.0600    1.5234
   7.0700    1.6797
   7.0800    1.5625
   7.0900    1.5234
   7.1000    1.4453
   7.1100    1.5625
   7.1200    1.4062
   7.1300    1.2109
   7.1400    1.8945
   7.1500    1.7187
   7.1600    1.6406
   7.1700    1.5430
   7.1800    1.3477
   7.1900    1.3867
   7.2000    1.5039
   7.2100    1.5234
   7.2200    1.7187
   7.2300    1.4648
   7.2400    0.9766
   7.2500    1.3672
   7.2600    1.5234
   7.2700    1.3281
   7.2800    1.2695
   7.2900    1.4062
   7.3000    1.4062
   7.3100    1.4453
   7.3200    1.6016
   7.3300    1.3477
   7.3400    1.1719
   7.3500    1.3281
   7.3600    1.2891
   7.3700    1.1328
   7.3800    1.3867
   7.3900    1.2891
   7.4000    1.4648
   7.4100    1.0937
   7.4200    1.3477
   7.4300    1.3086
   7.4400    1.0547
   7.4500    0.9961
   7.4600    1.2891
   7.4700    1.5234
   7.4800    1.2305
   7.4900    1.1914
   7.5000    1.4844
   7.5100    1.2891
   7.5200    1.2500
   7.5300    1.2695
   7.5400    1.4453
   7.5500    1.2109
   7.5600    1.2305
   7.5700    1.3281
   7.5800    0.9766
   7.5900    0.7812
   7.6000    0.9375
   7.6100    1.4453
   7.6200    1.0156
   7.6300    1.1914
   7.6400    1.2305
   7.6500    1.1523
   7.6600    1.3281
   7.6700    1.1914
   7.6800    1.2109
   7.6900    0.9961
   7.7000    1.0742
   7.7100    1.3281
   7.7200    1.1133
   7.7300    0.9180
   7.7400    0.9375
   7.7500    0.9180
   7.7600    0.9570
   7.7700    1.0352
   7.7800    1.0156
   7.7900    1.2109
   7.8000    0.9570
   7.8100    1.1914
   7.8200    1.1719
   7.8300    1.0547
   7.8400    1.0937
   7.8500    0.9375
   7.8600    1.0742
   7.8700    0.9375
   7.8800    1.2109
   7.8900    1.1328
   7.9000    0.9180
   7.9100    0.8984
   7.9200    0.9766
   7.9300    0.9766
   7.9400    0.9180
   7.9500    0.9180
   7.9600    0.7422
   7.9700    1.0547
   7.9800    0.8984
   7.9900    0.8984
   8.0000    1.0156
; (Data for Range number 3)
_DRIVE='COUPLED'
_STEPTIME=51.200001
_STEPSIZE=0.010000
_STEPMODE='S'
_START=0.200000
_THETA=0.250000
_2THETA=0.200000
_KHI=0.000000
_PHI=0.000000
_X=0.000000
_Y=0.000000
_Z=0.000000
_DIVERGENCE=0.000000
_ANTISCATTER=0.000000
_DETECTOR=1
; S.C.
_HV=799.799988
_GAIN=2.000000
_LLD=0.900000
_ULD=2.000000
_DETECTORSLIT='out'
_AUX1=0.000000
_AUX2=0.000000
_AUX3=0.000000
_DELAY=1.000000
_TIMESTARTED=37870.000000
_TEMP_RATE=-1.000000
_TEMP_DELAY=-1.000000
_KV=40
_MA=40
_RANGE_WL=1.540600
_3DPLANE=0
_2THETACPS
   0.2000    4567.0
   0.2100    3329.9
   0.2200    3113.3
   0.2300    3139.3
   0.2400    3191.2
   0.2500    3274.1
   0.2600    3339.8
   0.2700    3405.7
   0.2800    3453.0
   0.2900    3534.2
   0.3000    3614.7
   0.3100    3697.2
   0.3200    3726.2
   0.3300    3784.4
   0.3400    3912.0
   0.3500    4006.5
   0.3600    4064.6
   0.3700    4071.3
   0.3800    4173.8
   0.3900    4278.7
   0.4000    4371.4
   0.4100    4439.4
   0.4200    4544.3
   0.4300    4630.0
   0.4400    4689.8
   0.4500    4690.3
   0.4600    4724.2
   0.4700    4807.1
   0.4800    4901.9
   0.4900    5062.1
   0.5000    5241.3
   0.5100    5430.2
   0.5200    5527.8
   0.5300    5564.8
   0.5400    5590.0
   0.5500    5526.2
   0.5600    5452.1
   0.5700    5297.8
   0.5800    5173.1
   0.5900    4979.8
   0.6000    4801.5
   0.6100    4564.7
   0.6200    4356.4
   0.6300    4154.3
   0.6400    3944.1
   0.6500    3709.4
   0.6600    3502.2
   0.6700    3252.4
   0.6800    3026.1
   0.6900    2779.2
   0.7000    2557.6
   0.7100    2323.5
   0.7200    2113.2
   0.7300    1888.6
   0.7400    1708.6
   0.7500    1542.8
   0.7600    1381.1
   0.7700    1239.8
   0.7800    1114.1
   0.7900    999.51
   0.8000    904.75
   0.8100    829.06
   0.8200    760.18
   0.8300    705.92
   0.8400    653.32
   0.8500    599.82
   0.8600    570.21
   0.8700    544.73
   0.8800    517.27
   0.8900    495.45
   0.9000    474.47
   0.9100    451.93
   0.9200    436.17
   0.9300    424.80
   0.9400    411.17
   0.9500    390.88
   0.9600    381.62
   0.9700    361.33
   0.9800    340.45
   0.9900    322.44
   1.0000    309.49
   1.0100    288.38
   1.0200    276.11
   1.0300    253.96
   1.0400    234.90
   1.0500    221.19
   1.0600    204.67
   1.0700    188.18
   1.0800    175.92
   1.0900    162.77
   1.1000    147.13
   1.1100    139.20
   1.1200    125.90
   1.1300    118.69
   1.1400    108.34
   1.1500    104.80
   1.1600    99.199
   1.1700    93.711
   1.1800    92.656
   1.1900    89.082
   1.2000    89.863
   1.2100    87.793
   1.2200    88.281
   1.2300    87.422
   1.2400    88.281
   1.2500    87.656
   1.2600    87.676
   1.2700    90.762
   1.2800    89.336
   1.2900    90.254
   1.3000    91.582
   1.3100    91.309
   1.3200    90.156
   1.3300    90.586
   1.3400    89.590
   1.3500    89.297
   1.3600    85.898
   1.3700    82.793
   1.3800    80.742
   1.3900    79.141
   1.4000    74.082
   1.4100    73.594
   1.4200    69.629
   1.4300    68.164
   1.4400    65.625
   1.4500    62.051
   1.4600    57.559
   1.4700    54.805
   1.4800    52.168
   1.4900    49.102
   1.5000    44.824
   1.5100    43.066
   1.5200    41.953
   1.5300    39.023
   1.5400    36.465
   1.5500    36.230
   1.5600    33.066
   1.5700    34.766
   1.5800    31.016
   1.5900    31.211
   1.6000    30.020
   1.6100    28.691
   1.6200    29.922
   1.6300    29.160
   1.6400    29.258
   1.6500    28.574
   1.6600    28.633
   1.6700    28.613
   1.6800    29.336
   1.6900    27.461
   1.7000    29.453
   1.7100    29.219
   1.7200    26.758
   1.7300    25.898
   1.7400    27.676
   1.7500    27.090
   1.7600    25.078
   1.7700    25.039
   1.7800    24.316
   1.7900    24.277
   1.8000    23.594
   1.8100    23.867
   1.8200    23.203
   1.8300    21.094
   1.8400    20.508
   1.8500    19.395
   1.8600    20.039
   1.8700    18.672
   1.8800    18.184
   1.8900    16.621
   1.9000    15.703
   1.9100    16.211
   1.9200    16.230
   1.9300    14.355
   1.9400    13.672
   1.9500    13.477
   1.9600    13.477
   1.9700    13.203
   1.9800    12.012
   1.9900    12.207
   2.0000    12.207
   2.0100    12.012
   2.0200    11.484
   2.0300    10.781
   2.0400    10.957
   2.0500    11.582
   2.0600    11.230
   2.0700    11.641
   2.0800    11.523
   2.0900    10.371
   2.1000    11.465
   2.1100    11.465
   2.1200    10.508
   2.1300    12.344
   2.1400    11.367
   2.1500    10.820
   2.1600    11.016
   2.1700    10.586
   2.1800    10.371
   2.1900    11.211
   2.2000    10.859
   2.2100    9.8828
   2.2200    9.4727
   2.2300    9.7461
   2.2400    9.4727
   2.2500    9.3945
   2.2600    8.8867
   2.2700    8.6328
   2.2800    8.8672
   2.2900    7.9297
   2.3000    6.2109
   2.3100    6.8555
   2.3200    6.8555
   2.3300    6.1914
   2.3400    6.4062
   2.3500    6.1328
   2.3600    5.7227
   2.3700    5.4102
   2.3800    5.3125
   2.3900    5.6250
   2.4000    4.4727
   2.4100    4.4531
   2.4200    4.7656
   2.4300    4.8633
   2.4400    3.9648
   2.4500    4.1602
   2.4600    4.5508
   2.4700    4.4727
   2.4800    4.4141
   2.4900    4.7852
   2.5000    4.5898
   2.5100    4.1211
   2.5200    4.6680
   2.5300    4.9023
   2.5400    4.8047
   2.5500    4.3164
   2.5600    5.3711
   2.5700    5.0000
   2.5800    4.4336
   2.5900    5.0000
   2.6000    5.4492
   2.6100    4.8437
   2.6200    4.6875
   2.6300    4.7656
   2.6400    4.7852
   2.6500    5.3711
   2.6600    4.7070
   2.6700    5.0195
   2.6800    4.7852
   2.6900    5.0781
   2.7000    4.4727
   2.7100    4.2578
   2.7200    4.5117
   2.7300    3.9453
   2.7400    4.0039
   2.7500    4.1602
   2.7600    3.7500
   2.7700    3.9648
   2.7800    3.7891
   2.7900    4.1211
   2.8000    3.3789
   2.8100    3.3008
   2.8200    3.5937
   2.8300    3.5742
   2.8400    4.1992
   2.8500    2.8516
   2.8600    3.5547
   2.8700    2.9492
   2.8800    3.1445
   2.8900    3.2031
   2.9000    3.3398
   2.9100    3.2422
   2.9200    3.2812
   2.9300    3.7695
   2.9400    3.4180
   2.9500    3.3398
   2.9600    3.5937
   2.9700    3.3984
   2.9800    2.9492
   2.9900    3.7109
   3.0000    3.4570
   3.0100    3.6133
   3.0200    3.1055
   3.0300    3.5156
   3.0400    3.7500
   3.0500    3.2812
   3.0600    3.5352
   3.0700    3.2617
   3.0800    3.1250
   3.0900    2.9883
   3.1000    3.4180
   3.1100    2.9492
   3.1200    3.2422
   3.1300    2.8125
   3.1400    3.1445
   3.1500    2.7148
   3.1600    3.4180
   3.1700    2.7148
   3.1800    3.0273
   3.1900    3.1641
   3.2000    2.3047
   3.2100    2.6758
   3.2200    2.5781
   3.2300    2.1484
   3.2400    2.4609
   3.2500    2.5977
   3.2600    2.1484
   3.2700    2.4023
   3.2800    2.4609
   3.2900    2.4219
   3.3000    2.2656
   3.3100    2.5586
   3.3200    2.1875
   3.3300    1.9531
   3.3400    2.5391
   3.3500    1.9727
   3.3600    2.3242
   3.3700    2.5000
   3.3800    2.1289
   3.3900    2.3828
   3.4000    2.0703
   3.4100    2.3047
   3.4200    2.3047
   3.4300    2.0117
   3.4400    2.6758
   3.4500    2.3633
   3.4600    2.0703
   3.4700    2.2461
   3.4800    2.6758
   3.4900    2.4414
   3.5000    2.2070
   3.5100    2.1875
   3.5200    2.4219
   3.5300    2.3047
   3.5400    2.4609
   3.5500    2.3437
   3.5600    2.2070
   3.5700    2.0508
   3.5800    2.2852
   3.5900    2.4609
   3.6000    1.9727
   3.6100    1.7578
   3.6200    2.0703
   3.6300    1.9531
   3.6400    1.9531
   3.6500    2.1289
   3.6600    2.1094
   3.6700    1.8359
   3.6800    1.9727
   3.6900    1.9727
   3.7000    1.5820
   3.7100    2.0898
   3.7200    1.8750
   3.7300    1.8750
   3.7400    1.6406
   3.7500    1.8945
   3.7600    1.8750
   3.7700    2.1289
   3.7800    1.8555
   3.7900    1.9727
   3.8000    1.8359
   3.8100    2.0312
   3.8200    2.0898
   3.8300    1.9922
   3.8400    2.0703
   3.8500    2.0898
   3.8600    2.1289
   3.8700    2.1484
   3.8800    2.0117
   3.8900    1.8945
   3.9000    1.8164
   3.9100    1.8945
   3.9200    1.9727
   3.9300    2.0898
   3.9400    1.7773
   3.9500    1.7969
   3.9600    2.4023
   3.9700    1.6016
   3.9800    1.7187
   3.9900    1.9727
   4.0000    1.9531
   4.0100    1.8555
   4.0200    1.7187
   4.0300    1.5430
   4.0400    1.5234
   4.0500    1.7969
   4.0600    1.6992
   4.0700    1.6406
   4.0800    1.8164
   4.0900    1.6797
   4.1000    1.5234
   4.1100    1.4648
   4.1200    1.7578
   4.1300    1.4648
   4.1400    1.5625
   4.1500    1.6992
   4.1600    1.5820
   4.1700    1.5039
   4.1800    1.5234
   4.1900    1.6211
   4.2000    1.7383
   4.2100    1.5625
   4.2200    1.3477
   4.2300    1.1133
   4.2400    1.4648
   4.2500    1.4844
   4.2600    1.6211
   4.2700    1.7383
   4.2800    1.8359
   4.2900    1.7969
   4.3000    1.3281
   4.3100    1.7383
   4.3200    1.6406
   4.3300    1.3867
   4.3400    1.5625
   4.3500    1.4258
   4.3600    1.6992
   4.3700    1.5820
   4.3800    1.4453
   4.3900    1.5625
   4.4000    1.3867
   4.4100    1.6602
   4.4200    1.3672
   4.4300    1.3281
   4.4400    1.4648
   4.4500    1.6602
   4.4600    1.3672
   4.4700    1.6016
   4.4800    1.4062
   4.4900    1.2305
   4.5000    1.3281
   4.5100    1.4648
   4.5200    1.3867
   4.5300    0.9180
   4.5400    1.6992
   4.5500    1.3086
   4.5600    1.2305
   4.5700    1.2695
   4.5800    1.0352
   4.5900    1.1328
   4.6000    1.4844
   4.6100    1.5820
   4.6200    1.2305
   4.6300    1.2695
   4.6400    1.1523
   4.6500    1.1328
   4.6600    1.2109
   4.6700    1.1914
   4.6800    1.3281
   4.6900    0.9961
   4.7000    1.1914
   4.7100    1.1719
   4.7200    1.2305
   4.7300    1.0352
   4.7400    0.9961
   4.7500    1.3672
   4.7600    1.0156
   4.7700    1.0156
   4.7800    1.4844
   4.7900    1.0156
   4.8000    1.3086
   4.8100    1.1523
   4.8200    1.2305
   4.8300    0.8008
   4.8400    1.1523
   4.8500    0.9961
   4.8600    0.8594
   4.8700    1.0547
   4.8800    1.2109
   4.8900    1.2500
   4.9000    0.8789
   4.9100    1.1133
   4.9200    0.9180
   4.9300    1.0742
   4.9400    1.0937
   4.9500    0.9961
   4.9600    1.2500
   4.9700    1.0742
   4.9800    0.9180
   4.9900    1.1523
   5.0000    0.9570
   5.0100    0.8398
   5.0200    1.0352
   5.0300    1.2109
   5.0400    0.8789
   5.0500    1.0547
   5.0600    1.1914
   5.0700    1.0156
   5.0800    0.8984
   5.0900    1.2109
   5.1000    1.1133
   5.1100    0.8398
   5.1200    0.8203
   5.1300    1.3086
   5.1400    0.9180
   5.1500    0.8203
   5.1600    0.8789
   5.1700    0.9180
   5.1800    0.7617
   5.1900    0.9961
   5.2000    0.8398
   5.2100    1.1719
   5.2200    0.8594
   5.2300    0.8398
   5.2400    0.9961
   5.2500    0.8789
   5.2600    1.0742
   5.2700    0.8789
   5.2800    0.9766
   5.2900    0.8984
   5.3000    0.6641
   5.3100    1.1523
   5.3200    1.1328
   5.3300    0.9570
   5.3400    1.1133
   5.3500    0.7227
   5.3600    1.0352
   5.3700    1.1328
   5.3800    0.9180
   5.3900    1.1328
   5.4000    0.9961
   5.4100    1.3086
   5.4200    1.1719
   5.4300    0.8594
   5.4400    1.0352
   5.4500    0.9180
   5.4600    0.9375
   5.4700    0.9375
   5.4800    1.0742
   5.4900    0.9180
   5.5000    0.8008
   5.5100    0.8203
   5.5200    0.8008
   5.5300    0.8398
   5.5400    0.9961
   5.5500    1.0937
   5.5600    0.9180
   5.5700    0.9570
   5.5800    0.8203
   5.5900    1.0156
   5.6000    0.8984
   5.6100    0.8203
   5.6200    0.6836
   5.6300    1.2305
   5.6400    0.8984
   5.6500    0.9375
   5.6600    1.2109
   5.6700    0.9180
   5.6800    0.5859
   5.6900    0.6445
   5.7000    0.8789
   5.7100    1.0352
   5.7200    0.7031
   5.7300    0.8008
   5.7400    0.8984
   5.7500    0.7617
   5.7600    0.8789
   5.7700    0.8203
   5.7800    0.8594
   5.7900    0.8008
   5.8000    0.8008
   5.8100    0.8398
   5.8200    0.8789
   5.8300    0.8789
   5.8400    0.8789
   5.8500    1.0742
   5.8600    0.7227
   5.8700    0.6836
   5.8800    0.8203
   5.8900    0.6445
   5.9000    0.8203
   5.9100    0.6055
   5.9200    0.7617
   5.9300    0.7617
   5.9400    0.9570
   5.9500    0.8008
   5.9600    0.6250
   5.9700    0.7812
   5.9800    0.8984
   5.9900    0.6250
   6.0000    0.9961
   6.0100    0.8398
   6.0200    0.8398
   6.0300    0.7031
   6.0400    0.6641
   6.0500    0.7422
   6.0600    0.9180
   6.0700    0.7227
   6.0800    0.7227
   6.0900    0.7812
   6.1000    0.7812
   6.1100    0.5078
   6.1200    0.6445
   6.1300    0.5859
   6.1400    0.8398
   6.1500    0.4883
   6.1600    0.7422
   6.1700    0.7031
   6.1800    0.6250
   6.1900    0.8789
   6.2000    0.8984
   6.2100    0.7617
   6.2200    0.8008
   6.2300    0.7031
   6.2400    0.7031
   6.2500    0.8789
   6.2600    0.7227
   6.2700    0.5469
   6.2800    0.6641
   6.2900    0.8984
   6.3000    0.7422
   6.3100    0.7031
   6.3200    0.8398
   6.3300    0.7031
   6.3400    0.8398
   6.3500    0.7812
   6.3600    0.6641
   6.3700    0.6250
   6.3800    0.9375
   6.3900    0.8398
   6.4000    0.7031
   6.4100    0.4297
   6.4200    0.7812
   6.4300    0.5078
   6.4400    0.8008
   6.4500    0.5273
   6.4600    0.5273
   6.4700    0.5469
   6.4800    0.5469
   6.4900    0.7812
   6.5000    0.8594
   6.5100    0.7031
   6.5200    0.8203
   6.5300    0.5273
   6.5400    0.6836
   6.5500    0.5273
   6.5600    0.4687
   6.5700    0.6641
   6.5800    0.5859
   6.5900    0.6836
   6.6000    0.6250
   6.6100    0.5859
   6.6200    0.6055
   6.6300    0.5273
   6.6400    0.6445
   6.6500    0.6445
   6.6600    0.3125
   6.6700    0.7617
   6.6800    0.4883
   6.6900    0.4883
   6.7000    0.4102
   6.7100    0.5469
   6.7200    0.5078
   6.7300    0.6055
   6.7400    0.5859
   6.7500    0.5273
   6.7600    0.7422
   6.7700    0.8008
   6.7800    0.5078
   6.7900    0.4492
   6.8000    0.5859
   6.8100    0.5664
   6.8200    0.4492
   6.8300    0.7031
   6.8400    0.4883
   6.8500    0.7812
   6.8600    0.8203
   6.8700    0.8008
   6.8800    0.6445
   6.8900    0.7422
   6.9000    0.5469
   6.9100    0.8203
   6.9200    0.5859
   6.9300    0.4883
   6.9400    0.5859
   6.9500    0.6055
   6.9600    0.6641
   6.9700    0.4883
   6.9800    0.5078
   6.9900    0.4883
   7.0000    0.6055
   7.0100    0.7031
   7.0200    0.7031
   7.0300    0.6055
   7.0400    0.4492
   7.0500    0.5273
   7.0600    0.3711
   7.0700    0.5273
   7.0800    0.6641
   7.0900    0.6445
   7.1000    0.5664
   7.1100    0.6250
   7.1200    0.5273
   7.1300    0.6445
   7.1400    0.6250
   7.1500    0.5273
   7.1600    0.4492
   7.1700    0.3711
   7.1800    0.5664
   7.1900    0.8008
   7.2000    0.3125
   7.2100    0.4492
   7.2200    0.5469
   7.2300    0.5469
   7.2400    0.5859
   7.2500    0.4883
   7.2600    0.4492
   7.2700    0.6055
   7.2800    0.5078
   7.2900    0.5664
   7.3000    0.5859
   7.3100    0.4687
   7.3200    0.6055
   7.3300    0.5273
   7.3400    0.6445
   7.3500    0.5859
   7.3600    0.7617
   7.3700    0.3711
   7.3800    0.5273
   7.3900    0.4687
   7.4000    0.3711
   7.4100    0.5469
   7.4200    0.4492
   7.4300    0.5078
   7.4400    0.4687
   7.4500    0.4883
   7.4600    0.5469
   7.4700    0.4102
   7.4800    0.6250
   7.4900    0.3711
   7.5000    0.5469
   7.5100    0.4883
   7.5200    0.4687
   7.5300    0.3516
   7.5400    0.4883
   7.5500    0.6055
   7.5600    0.5078
   7.5700    0.5859
   7.5800    0.5273
   7.5900    0.5078
   7.6000    0.5664
   7.6100    0.4492
   7.6200    0.3906
   7.6300    0.4297
   7.6400    0.3711
   7.6500    0.4102
   7.6600    0.4492
   7.6700    0.6641
   7.6800    0.3320
   7.6900    0.6836
   7.7000    0.5664
   7.7100    0.5469
   7.7200    0.6055
   7.7300    0.5859
   7.7400    0.5469
   7.7500    0.6055
   7.7600    0.6055
   7.7700    0.6641
   7.7800    0.5859
   7.7900    0.6445
   7.8000    0.5078
   7.8100    0.6055
   7.8200    0.6250
   7.8300    0.5859
   7.8400    0.5078
   7.8500    0.6055
   7.8600    0.5469
   7.8700    0.4687
   7.8800    0.4102
   7.8900    0.4297
   7.9000    0.5469
   7.9100    0.4883
   7.9200    0.6250
   7.9300    0.5469
   7.9400    0.8203
   7.9500    0.4883
   7.9600    0.5859
   7.9700    0.6445
   7.9800    0.5273
   7.9900    0.4102
   8.0000    0.6250